## –ü–µ—Ä–µ—Ö–æ–¥–∏–º –Ω–∞ –≥–∏–±–∫–∏–µ —Å—Ü–µ–Ω–∞—Ä–∏–∏

–ù–∞ –¥–∞–Ω–Ω—ã–π –º–æ–º–µ–Ω—Ç:

–£–¥–∞–ª–æ—Å—å –∑–∞–ø—É—Å—Ç–∏—Ç—å –æ–±—â—É—é –ª–æ–≥–∏–∫—É —É–ø—Ä–∞–≤–ª–µ–Ω–∏—è.
–£–¥–∞–ª–æ—Å—å –∑–∞–ø—É—Å—Ç–∏—Ç—å –≠–û–°–°
–£–¥–∞–ª–æ—Å—å –∑–∞–ø—É—Å—Ç–∏—Ç—å —Å—Ç–∞—Ç—É
–ò —Å—Ç–µ–π—Ç-–º–∞—à–∏–Ω—É —Å –≥–æ—Ä–µ–º –ø–æ–ø–æ–ª–∞–º

–ü—Ä–æ–±–ª–µ–º—ã:

1. –í –Ω–µ–∫–æ—Ç–æ—Ä—ã—Ö —Å–ª—É—á–∞—è—Ö –Ω–µ –Ω–∞–∂–∏–º–∞—é—Ç—Å—è –∫–Ω–æ–ø–∫–∏ —Å –ø–µ—Ä–≤–æ–≥–æ —Ä–∞–∑–∞. –°–∫–æ—Ä–µ–µ –≤—Å–µ–≥–æ ‚Äî –∏–∑-–∑–∞ –æ–≥—Ä–∞–Ω–∏—á–µ–Ω–∏–π –Ω–∞ next_state

2. –ö–∞–∂–µ—Ç—Å—è, —á—Ç–æ —É –Ω–∞—Å –æ—à–∏–±–∫–∞ –≤ –ª–æ–≥–∏–∫–µ, –∑–∞–ø—Ä–µ—â–∞—é—â–∞—è –Ω–∞–º –ø–µ—Ä–µ—Å–∫–æ—á–∏—Ç—å –Ω–∞ –¥—Ä—É–≥—É—é –≤–µ—Ç–∫—É.

3. –ì–æ–ª–æ—Å–∞ –Ω–µ –ø—Ä–æ—Ö–æ–¥—è—Ç, —Å–∫–æ—Ä–µ–µ –≤—Å–µ–≥–æ –∏–∑-–∑–∞ —Ç–æ–≥–æ –∂–µ

```
basic_handler
get_user_id
{'poll_answer': {'user': {'last_name': '–¶—É–ø–∫–æ', 'id': 24442585, 'is_bot': False, 'first_name': '–ò–≥–æ—Ä—å', 'language_code': 'ru', 'username': 'i_tsupko'}, 'poll_id': '5226957452427133380', 'option_ids': [1]}, 'update_id': 617129490}
user User object (1) in state
[ eoss_initiate[3] ]
handler_type
<class 'telegram.ext.pollanswerhandler.PollAnswerHandler'>
possible_states
dict_keys([])
fallback to  <class 'tbot.exceptions.silent_exception.SilentException'>
<class 'tbot.exceptions.silent_exception.SilentException'>
Runned class Silent
basic_handler
get_user_id
{'poll_answer': {'user': {'id': 325806629, 'is_bot': False, 'first_name': 'petr', 'username': 'paintthetow'}, 'poll_id': '5226957452427133380', 'option_ids': [0]}, 'update_id': 617129492}
user User object (3) in state
[ menu ]
fallback to  <class 'tbot.exceptions.fallback_to_menu.FallbackToMenu'>
<class 'tbot.exceptions.fallback_to_menu.FallbackToMenu'>
Runned class Menu
2022-05-27 16:42:55,153 - telegram.ext.dispatcher - ERROR - No error handlers are registered, logging exception.
Traceback (most recent call last):
  File "/Users/igor.tsupko/web/may-cat.github/eoss-bot/django-app/tbot/convmachine.py", line 200, in _basic_handler
    possible_states = self._get_next_possible_states(user_state, handler_type)
  File "/Users/igor.tsupko/web/may-cat.github/eoss-bot/django-app/tbot/convmachine.py", line 251, in _get_next_possible_states
    raise FallbackToMenu
tbot.exceptions.fallback_to_menu.FallbackToMenu

During handling of the above exception, another exception occurred:

Traceback (most recent call last):
  File "/usr/local/lib/python3.9/site-packages/telegram/ext/dispatcher.py", line 555, in process_update
    handler.handle_update(update, self, check, context)
  File "/usr/local/lib/python3.9/site-packages/telegram/ext/handler.py", line 198, in handle_update
    return self.callback(update, context)
  File "/Users/igor.tsupko/web/may-cat.github/eoss-bot/django-app/tbot/convmachine.py", line 190, in _custom_poll_answer_handler
    self._basic_handler(update, context, PollAnswerHandler)
  File "/Users/igor.tsupko/web/may-cat.github/eoss-bot/django-app/tbot/convmachine.py", line 222, in _basic_handler
    self.fallbacks[exception_type]['handler'].handle(update=update, context=context, user=user)
  File "/Users/igor.tsupko/web/may-cat.github/eoss-bot/django-app/tbot/lib/handler.py", line 68, in handle
    self.run(update, context, user)
  File "/Users/igor.tsupko/web/may-cat.github/eoss-bot/django-app/tbot/handlers/menu.py", line 44, in run
    update.message.reply_text("üè† –î–æ–±—Ä–æ –ø–æ–∂–∞–ª–æ–≤–∞—Ç—å –¥–æ–º–æ–π, –≤—ã–±–µ—Ä–∏—Ç–µ –¥–µ–π—Å—Ç–≤–∏–µ:", reply_markup=markup)
AttributeError: 'NoneType' object has no attribute 'reply_text'
```


–ß—Ç–æ –Ω—É–∂–Ω–æ —Å–¥–µ–ª–∞—Ç—å

- –ü—Ä–æ—Ç–µ—Å—Ç–∏—Ä–æ–≤–∞—Ç—å –≤—Å–µ –ø—Ä–∞–≤–∏–ª—å–Ω—ã–µ —Å—Ü–µ–Ω–∞—Ä–∏–∏
- –ü—Ä–æ—Ç–µ—Å—Ç–∏—Ä–æ–≤–∞—Ç—å –Ω–µ–ø—Ä–∞–≤–∏–ª—å–Ω—ã–µ —Å—Ü–µ–Ω–∞—Ä–∏–∏ (–Ω–∞–ø—Ä–∏–º–µ—Ä, –æ—Ç–ø—Ä–∞–≤–∫—É –æ–ø—Ä–æ—Å–∞ –Ω–µ –≤–æ–≤—Ä–µ–º—è –∏–ª–∏ –Ω–µ —Ç–∞–º)